Traceback (most recent call last):
  File "/Users/quannguyen/opt/miniconda3/lib/python3.8/site-packages/jupyter_cache/executors/utils.py", line 51, in single_nb_execution
    executenb(
  File "/Users/quannguyen/opt/miniconda3/lib/python3.8/site-packages/nbclient/client.py", line 1112, in execute
    return NotebookClient(nb=nb, resources=resources, km=km, **kwargs).execute()
  File "/Users/quannguyen/opt/miniconda3/lib/python3.8/site-packages/nbclient/util.py", line 74, in wrapped
    return just_run(coro(*args, **kwargs))
  File "/Users/quannguyen/opt/miniconda3/lib/python3.8/site-packages/nbclient/util.py", line 53, in just_run
    return loop.run_until_complete(coro)
  File "/Users/quannguyen/opt/miniconda3/lib/python3.8/asyncio/base_events.py", line 616, in run_until_complete
    return future.result()
  File "/Users/quannguyen/opt/miniconda3/lib/python3.8/site-packages/nbclient/client.py", line 553, in async_execute
    await self.async_execute_cell(
  File "/Users/quannguyen/opt/miniconda3/lib/python3.8/site-packages/nbclient/client.py", line 857, in async_execute_cell
    self._check_raise_for_error(cell, exec_reply)
  File "/Users/quannguyen/opt/miniconda3/lib/python3.8/site-packages/nbclient/client.py", line 760, in _check_raise_for_error
    raise CellExecutionError.from_cell_and_msg(cell, exec_reply_content)
nbclient.exceptions.CellExecutionError: An error occurred while executing the following cell:
------------------
# options(warn=-1)

# actcal <- data.frame(lapply(actcal, function(x) { gsub("^A\\b", "Read", x)}))
# actcal <- data.frame(lapply(actcal, function(x) { gsub("^B\\b", "Watch", x)}))
# actcal <- data.frame(lapply(actcal, function(x) { gsub("^C\\b", "Discuss", x)}))
# actcal <- data.frame(lapply(actcal, function(x) { gsub("^D\\b", "Practice", x)}))
# actcal.seq <- seqdef(actcal, var = 13:24)
# actcal.seq
seqiplot(actcal.seq, main = "Index plot (first 10 sequences)",with.legend = TRUE)
------------------

Error in seqplot(seqdata, group = group, type = "i", main = main, ...): object 'actcal.seq' not found
Traceback:

1. seqiplot(actcal.seq, main = "Index plot (first 10 sequences)", 
 .     with.legend = TRUE)
2. seqplot(seqdata, group = group, type = "i", main = main, ...)
ERROR: Error in seqplot(seqdata, group = group, type = "i", main = main, ...): object 'actcal.seq' not found


